●非同期処理で発生した例外の処理
同期メソッド実行時と同様にtry-catch文で拾うことができる

 [注意]
 VisualStudioのビルド設定が "Debug" のとき,例外を発生スレッドでcatchできなかった場合は実行が中断され,その通知がVS上に表示される
  -awaitやTask.Runをtry文の内部に記述した場合でも,catch文に移行する前に実行が中断される
   "続行" をクリックすれば,catch文に移行できる

Task.WhenAll(タスクの列) などで複数の例外が同時に発生した場合は,

 catch
 {
    foreach (Exeption ex in タスクの列.Exeption.InnerExeptions)
    { (処理) }
 }

のように,foreachを用いればよい
